[2022-11-18T00:00:46.611+0000] {taskinstance.py:1165} INFO - Dependencies all met for <TaskInstance: xcom_dag.t2 scheduled__2022-11-17T00:00:00+00:00 [queued]>
[2022-11-18T00:00:46.849+0000] {taskinstance.py:1165} INFO - Dependencies all met for <TaskInstance: xcom_dag.t2 scheduled__2022-11-17T00:00:00+00:00 [queued]>
[2022-11-18T00:00:46.853+0000] {taskinstance.py:1362} INFO - 
--------------------------------------------------------------------------------
[2022-11-18T00:00:46.856+0000] {taskinstance.py:1363} INFO - Starting attempt 1 of 1
[2022-11-18T00:00:46.867+0000] {taskinstance.py:1364} INFO - 
--------------------------------------------------------------------------------
[2022-11-18T00:00:47.022+0000] {taskinstance.py:1383} INFO - Executing <Task(PythonOperator): t2> on 2022-11-17 00:00:00+00:00
[2022-11-18T00:00:47.089+0000] {standard_task_runner.py:55} INFO - Started process 1072 to run task
[2022-11-18T00:00:47.109+0000] {standard_task_runner.py:82} INFO - Running: ['***', 'tasks', 'run', 'xcom_dag', 't2', 'scheduled__2022-11-17T00:00:00+00:00', '--job-id', '136', '--raw', '--subdir', 'DAGS_FOLDER/xcom_dag.py', '--cfg-path', '/tmp/tmps8f5wtra']
[2022-11-18T00:00:47.114+0000] {standard_task_runner.py:83} INFO - Job 136: Subtask t2
[2022-11-18T00:00:47.820+0000] {task_command.py:376} INFO - Running <TaskInstance: xcom_dag.t2 scheduled__2022-11-17T00:00:00+00:00 [running]> on host 9acdffb18527
[2022-11-18T00:00:49.040+0000] {taskinstance.py:1592} INFO - Exporting the following env vars:
AIRFLOW_CTX_DAG_OWNER=***
AIRFLOW_CTX_DAG_ID=xcom_dag
AIRFLOW_CTX_TASK_ID=t2
AIRFLOW_CTX_EXECUTION_DATE=2022-11-17T00:00:00+00:00
AIRFLOW_CTX_TRY_NUMBER=1
AIRFLOW_CTX_DAG_RUN_ID=scheduled__2022-11-17T00:00:00+00:00
[2022-11-18T00:00:49.077+0000] {taskinstance.py:1851} ERROR - Task failed with exception
Traceback (most recent call last):
  File "/home/airflow/.local/lib/python3.7/site-packages/airflow/operators/python.py", line 175, in execute
    return_value = self.execute_callable()
  File "/home/airflow/.local/lib/python3.7/site-packages/airflow/operators/python.py", line 193, in execute_callable
    return self.python_callable(*self.op_args, **self.op_kwargs)
  File "/opt/airflow/dags/xcom_dag.py", line 11, in _t2
    ti.xcom_pull(key = "my_key", task_id = "t1")
  File "/home/airflow/.local/lib/python3.7/site-packages/airflow/utils/session.py", line 75, in wrapper
    return func(*args, session=session, **kwargs)
TypeError: xcom_pull() got an unexpected keyword argument 'task_id'
[2022-11-18T00:00:49.255+0000] {taskinstance.py:1406} INFO - Marking task as FAILED. dag_id=xcom_dag, task_id=t2, execution_date=20221117T000000, start_date=20221118T000046, end_date=20221118T000049
[2022-11-18T00:00:49.582+0000] {standard_task_runner.py:105} ERROR - Failed to execute job 136 for task t2 (xcom_pull() got an unexpected keyword argument 'task_id'; 1072)
[2022-11-18T00:00:49.889+0000] {local_task_job.py:164} INFO - Task exited with return code 1
[2022-11-18T00:00:50.069+0000] {local_task_job.py:273} INFO - 0 downstream tasks scheduled from follow-on schedule check
