[2022-11-09T23:24:54.670+0000] {taskinstance.py:1165} INFO - Dependencies all met for <TaskInstance: producer.update_dataset manual__2022-11-09T23:24:32.485335+00:00 [queued]>
[2022-11-09T23:24:54.798+0000] {taskinstance.py:1165} INFO - Dependencies all met for <TaskInstance: producer.update_dataset manual__2022-11-09T23:24:32.485335+00:00 [queued]>
[2022-11-09T23:24:54.822+0000] {taskinstance.py:1362} INFO - 
--------------------------------------------------------------------------------
[2022-11-09T23:24:54.824+0000] {taskinstance.py:1363} INFO - Starting attempt 1 of 1
[2022-11-09T23:24:54.826+0000] {taskinstance.py:1364} INFO - 
--------------------------------------------------------------------------------
[2022-11-09T23:24:55.031+0000] {taskinstance.py:1383} INFO - Executing <Task(_PythonDecoratedOperator): update_dataset> on 2022-11-09 23:24:32.485335+00:00
[2022-11-09T23:24:55.071+0000] {standard_task_runner.py:55} INFO - Started process 688 to run task
[2022-11-09T23:24:55.132+0000] {standard_task_runner.py:82} INFO - Running: ['***', 'tasks', 'run', 'producer', 'update_dataset', 'manual__2022-11-09T23:24:32.485335+00:00', '--job-id', '21', '--raw', '--subdir', 'DAGS_FOLDER/producer.py', '--cfg-path', '/tmp/tmphvt0h5bq']
[2022-11-09T23:24:55.136+0000] {standard_task_runner.py:83} INFO - Job 21: Subtask update_dataset
[2022-11-09T23:24:56.048+0000] {task_command.py:376} INFO - Running <TaskInstance: producer.update_dataset manual__2022-11-09T23:24:32.485335+00:00 [running]> on host 75c039262b8c
[2022-11-09T23:24:57.203+0000] {taskinstance.py:1592} INFO - Exporting the following env vars:
AIRFLOW_CTX_DAG_OWNER=***
AIRFLOW_CTX_DAG_ID=producer
AIRFLOW_CTX_TASK_ID=update_dataset
AIRFLOW_CTX_EXECUTION_DATE=2022-11-09T23:24:32.485335+00:00
AIRFLOW_CTX_TRY_NUMBER=1
AIRFLOW_CTX_DAG_RUN_ID=manual__2022-11-09T23:24:32.485335+00:00
[2022-11-09T23:24:57.213+0000] {taskinstance.py:1851} ERROR - Task failed with exception
Traceback (most recent call last):
  File "/home/airflow/.local/lib/python3.7/site-packages/airflow/decorators/base.py", line 188, in execute
    return_value = super().execute(context)
  File "/home/airflow/.local/lib/python3.7/site-packages/airflow/operators/python.py", line 175, in execute
    return_value = self.execute_callable()
  File "/home/airflow/.local/lib/python3.7/site-packages/airflow/operators/python.py", line 193, in execute_callable
    return self.python_callable(*self.op_args, **self.op_kwargs)
  File "/opt/airflow/dags/producer.py", line 17, in update_dataset
    with open(my_file.uri, "w+") as f:
FileNotFoundError: [Errno 2] No such file or directory: 'tmp/my_file.txt'
[2022-11-09T23:24:57.340+0000] {taskinstance.py:1406} INFO - Marking task as FAILED. dag_id=producer, task_id=update_dataset, execution_date=20221109T232432, start_date=20221109T232454, end_date=20221109T232457
[2022-11-09T23:24:57.561+0000] {standard_task_runner.py:105} ERROR - Failed to execute job 21 for task update_dataset ([Errno 2] No such file or directory: 'tmp/my_file.txt'; 688)
[2022-11-09T23:24:57.670+0000] {local_task_job.py:164} INFO - Task exited with return code 1
[2022-11-09T23:24:57.925+0000] {local_task_job.py:273} INFO - 0 downstream tasks scheduled from follow-on schedule check
