[2022-11-09 08:18:12,204] {taskinstance.py:1159} INFO - Dependencies all met for <TaskInstance: user_processing.is_api_availible scheduled__2022-11-08T00:00:00+00:00 [queued]>
[2022-11-09 08:18:12,423] {taskinstance.py:1159} INFO - Dependencies all met for <TaskInstance: user_processing.is_api_availible scheduled__2022-11-08T00:00:00+00:00 [queued]>
[2022-11-09 08:18:12,455] {taskinstance.py:1356} INFO - 
--------------------------------------------------------------------------------
[2022-11-09 08:18:12,471] {taskinstance.py:1357} INFO - Starting attempt 1 of 1
[2022-11-09 08:18:12,475] {taskinstance.py:1358} INFO - 
--------------------------------------------------------------------------------
[2022-11-09 08:18:12,764] {taskinstance.py:1377} INFO - Executing <Task(HttpSensor): is_api_availible> on 2022-11-08 00:00:00+00:00
[2022-11-09 08:18:12,900] {standard_task_runner.py:52} INFO - Started process 6915 to run task
[2022-11-09 08:18:12,987] {standard_task_runner.py:79} INFO - Running: ['***', 'tasks', 'run', 'user_processing', 'is_api_availible', 'scheduled__2022-11-08T00:00:00+00:00', '--job-id', '6', '--raw', '--subdir', 'DAGS_FOLDER/user_processing.py', '--cfg-path', '/tmp/tmpg0739dvy', '--error-file', '/tmp/tmp_fhtmr55']
[2022-11-09 08:18:13,007] {standard_task_runner.py:80} INFO - Job 6: Subtask is_api_availible
[2022-11-09 08:18:14,440] {task_command.py:369} INFO - Running <TaskInstance: user_processing.is_api_availible scheduled__2022-11-08T00:00:00+00:00 [running]> on host ce8aab517b0f
[2022-11-09 08:18:15,980] {taskinstance.py:1571} INFO - Exporting the following env vars:
AIRFLOW_CTX_DAG_OWNER=***
AIRFLOW_CTX_DAG_ID=user_processing
AIRFLOW_CTX_TASK_ID=is_api_availible
AIRFLOW_CTX_EXECUTION_DATE=2022-11-08T00:00:00+00:00
AIRFLOW_CTX_TRY_NUMBER=1
AIRFLOW_CTX_DAG_RUN_ID=scheduled__2022-11-08T00:00:00+00:00
[2022-11-09 08:18:16,028] {http.py:97} INFO - Poking: api/
[2022-11-09 08:18:16,431] {taskinstance.py:1889} ERROR - Task failed with exception
Traceback (most recent call last):
  File "/home/airflow/.local/lib/python3.7/site-packages/airflow/sensors/base.py", line 277, in execute
    poke_return = self.poke(context)
  File "/home/airflow/.local/lib/python3.7/site-packages/airflow/providers/http/sensors/http.py", line 112, in poke
    raise exc
  File "/home/airflow/.local/lib/python3.7/site-packages/airflow/providers/http/sensors/http.py", line 103, in poke
    extra_options=self.extra_options,
  File "/home/airflow/.local/lib/python3.7/site-packages/airflow/providers/http/hooks/http.py", line 114, in run
    session = self.get_conn(headers)
  File "/home/airflow/.local/lib/python3.7/site-packages/airflow/providers/http/hooks/http.py", line 68, in get_conn
    conn = self.get_connection(self.http_conn_id)
  File "/home/airflow/.local/lib/python3.7/site-packages/airflow/hooks/base.py", line 67, in get_connection
    conn = Connection.get_connection_from_secrets(conn_id)
  File "/home/airflow/.local/lib/python3.7/site-packages/airflow/models/connection.py", line 430, in get_connection_from_secrets
    raise AirflowNotFoundException(f"The conn_id `{conn_id}` isn't defined")
airflow.exceptions.AirflowNotFoundException: The conn_id `user_api` isn't defined
[2022-11-09 08:18:16,553] {taskinstance.py:1400} INFO - Marking task as FAILED. dag_id=user_processing, task_id=is_api_availible, execution_date=20221108T000000, start_date=20221109T081812, end_date=20221109T081816
[2022-11-09 08:18:16,654] {standard_task_runner.py:97} ERROR - Failed to execute job 6 for task is_api_availible (The conn_id `user_api` isn't defined; 6915)
[2022-11-09 08:18:16,752] {local_task_job.py:156} INFO - Task exited with return code 1
[2022-11-09 08:18:17,757] {local_task_job.py:273} INFO - 0 downstream tasks scheduled from follow-on schedule check
